#VRML_SIM R2021b utf8
WorldInfo {
  basicTimeStep 16
  coordinateSystem "NUE"
}
Viewpoint {
  orientation -0.022289386747373845 -0.8722880849808676 -0.4884840632393618 3.191984503558162
  position -0.06935183702474146 3.997170089932513 -3.66855287062422
}
TexturedBackground {
}
TexturedBackgroundLight {
}
Robot {
  translation -0.7675058405877084 0.03986048964933697 0.026977526333201215
  rotation 1.6815055895616242e-08 1 -3.02480085667182e-09 -2.785596974758235
  children [
    DEF BODY Shape {
      appearance PBRAppearance {
        baseColor 0.917647 0.145098 0.145098
        roughness 1
        metalness 0
      }
      geometry Box {
        size 0.1 0.05 0.2
      }
    }
    DEF WHEEL1 HingeJoint {
      jointParameters HingeJointParameters {
        position 8.207996607253925
        anchor 0.06 0 0.05
      }
      device [
        RotationalMotor {
          name "wheel1"
        }
      ]
      endPoint Solid {
        translation 0.06 0 0.05
        rotation -0.6343411211116675 0.6343434511809903 -0.4418367662503691 3.973679293559203
        children [
          DEF WHEEL Shape {
            appearance PBRAppearance {
              baseColor 0.305882 0.898039 0.25098
              roughness 1
              metalness 0
            }
            geometry Cylinder {
              height 0.02
              radius 0.04
              subdivision 24
            }
          }
        ]
        boundingObject USE WHEEL
        physics Physics {
        }
        linearVelocity -0.013940947626297502 5.297283061082342e-09 -0.0374920001220315
        angularVelocity -0.9372999671395045 4.185293788852905e-09 0.34852370332925325
      }
    }
    DEF WHEEL2 HingeJoint {
      jointParameters HingeJointParameters {
        position 8.207996721077425
        anchor -0.06 0 0.05
      }
      device [
        RotationalMotor {
          name "wheel2"
        }
      ]
      endPoint Solid {
        translation -0.06 0 0.05
        rotation -0.634341136138969 0.6343434662083469 -0.44183672310108146 3.9736792213562753
        children [
          USE WHEEL
        ]
        name "solid(1)"
        boundingObject USE WHEEL
        physics Physics {
        }
        linearVelocity -0.013940946808333085 -5.297359433958782e-09 -0.037491997922180706
        angularVelocity -0.9372999669640877 4.185294625129948e-09 0.3485237032639995
      }
    }
    DEF WHEEL3 HingeJoint {
      jointParameters HingeJointParameters {
        position 8.207997308336243
        anchor 0.06 0 -0.05
      }
      device [
        RotationalMotor {
          name "wheel3"
        }
      ]
      endPoint Solid {
        translation 0.06 0 -0.05
        rotation -0.6343412136705138 0.6343435437401765 -0.44183650047746653 3.973678848833827
        children [
          USE WHEEL
        ]
        name "solid(2)"
        boundingObject USE WHEEL
        physics Physics {
        }
        linearVelocity -0.013940949456760238 5.297032141996151e-09 -0.03749199944139572
        angularVelocity -0.937299967126646 4.1784135515517525e-09 0.3485237033638356
      }
    }
    DEF WHEEL4 HingeJoint {
      jointParameters HingeJointParameters {
        position 8.207997409901425
        anchor -0.06 0 -0.05
      }
      device [
        RotationalMotor {
          name "wheel4"
        }
      ]
      endPoint Solid {
        translation -0.06 0 -0.05
        rotation -0.634341227079427 0.6343435571491389 -0.4418364619751795 3.9736787844068453
        children [
          USE WHEEL
        ]
        name "solid(3)"
        boundingObject USE WHEEL
        physics Physics {
        }
        linearVelocity -0.01394094863879634 -5.2976104728257e-09 -0.0374919972415447
        angularVelocity -0.9372999669512201 4.17841301118142e-09 0.348523703298605
      }
    }
    DEF DS_RIGHT DistanceSensor {
      translation -0.03 0 0.1
      rotation 0 1 0 -1.87079
      children [
        Shape {
          appearance PBRAppearance {
            baseColor 0.184314 0.596078 0.847059
            roughness 1
            metalness 0
          }
          geometry Box {
            size 0.01 0.01 0.01
          }
        }
      ]
      name "ds_right"
    }
    DEF DS_LEFT DistanceSensor {
      translation 0.03 0 0.1
      rotation 0 1 0 -1.27079
      children [
        Shape {
          appearance PBRAppearance {
            baseColor 0.184314 0.596078 0.847059
            roughness 1
            metalness 0
          }
          geometry Box {
            size 0.01 0.01 0.01
          }
        }
      ]
      name "ds_left"
    }
  ]
  boundingObject USE BODY
  physics Physics {
    density -1
    mass 1
  }
  controller "four_wheels_collision_avoidance"
  controllerArgs [
    ""
    ""
    ""
    ""
    ""
    ""
    ""
    ""
  ]
  linearVelocity -0.013940948132546427 -1.6361265323967451e-13 -0.03749199868178828
  angularVelocity -3.138372224444554e-08 -2.8672528149044122e-08 -8.440891983230545e-08
}
RectangleArena {
  floorSize 5 5
  floorTileSize 1 1
}
Obstacle {
  translation -1.65 0.025 1.28
}
Obstacle {
  translation 1.09 0.025 -1.05
  name "obstacle(1)"
}
Obstacle {
  translation -1.4 0.025 -1.48
  name "obstacle(2)"
}
Obstacle {
  translation 0 0.025 1.74
  name "obstacle(3)"
}
Obstacle {
  translation -0.5 0.025 -2.04
  name "obstacle(4)"
}
Obstacle {
  translation 0.78 0.025 1.1
  name "obstacle(5)"
}
Obstacle {
  translation -1.41 0.025 0
  name "obstacle(6)"
}
Obstacle {
  translation 0 0.025 -1.38
  name "obstacle(7)"
}
Obstacle {
  translation 1.29 0.025 0
  name "obstacle(8)"
}
