#VRML_SIM R2021b utf8
WorldInfo {
  basicTimeStep 16
  coordinateSystem "NUE"
}
Viewpoint {
  orientation -0.022289386747373845 -0.8722880849808676 -0.4884840632393618 3.191984503558162
  position -0.06935183702474146 3.997170089932513 -3.66855287062422
}
TexturedBackground {
}
TexturedBackgroundLight {
}
Robot {
  translation -1.286379612818611 0.039860490662285225 -0.17412071113770985
  rotation 7.311284331561991e-09 0.9999999999999998 2.2110662075894552e-08 -2.440468333281647
  children [
    DEF BODY Shape {
      appearance PBRAppearance {
        baseColor 0.917647 0.145098 0.145098
        roughness 1
        metalness 0
      }
      geometry Box {
        size 0.1 0.05 0.2
      }
    }
    DEF WHEEL1 HingeJoint {
      jointParameters HingeJointParameters {
        position 4659.967405877268
        anchor 0.06 0 0.05
      }
      device [
        RotationalMotor {
          name "wheel1"
        }
      ]
      endPoint Solid {
        translation 0.06 0 0.05
        rotation -0.6610641464063863 0.661066574635042 0.3549439085775222 2.4594501995700306
        children [
          DEF WHEEL Shape {
            appearance PBRAppearance {
              baseColor 0.305882 0.898039 0.25098
              roughness 1
              metalness 0
            }
            geometry Cylinder {
              height 0.02
              radius 0.04
              subdivision 24
            }
          }
        ]
        boundingObject USE WHEEL
        physics Physics {
        }
        linearVelocity -0.0002616682682620888 6.093457734025679e-09 -0.0278026516847097
        angularVelocity -0.7622463054495358 -0.35618820407152935 0.6472919440646785
      }
    }
    DEF WHEEL2 HingeJoint {
      jointParameters HingeJointParameters {
        position 3858.4645376043677
        anchor -0.06 0 0.05
      }
      device [
        RotationalMotor {
          name "wheel2"
        }
      ]
      endPoint Solid {
        translation -0.06 0 0.05
        rotation 0.2786529289201186 -0.27865395247135905 0.9190780815449409 1.6550842158536518
        children [
          USE WHEEL
        ]
        name "solid(1)"
        boundingObject USE WHEEL
        physics Physics {
        }
        linearVelocity 0.027390408060073222 -1.892107505052753e-08 0.004759157864424177
        angularVelocity 0.7622457105796684 -0.3561883633816547 -0.6472920044452644
      }
    }
    DEF WHEEL3 HingeJoint {
      jointParameters HingeJointParameters {
        position 4659.967448064298
        anchor 0.06 0 -0.05
      }
      device [
        RotationalMotor {
          name "wheel3"
        }
      ]
      endPoint Solid {
        translation 0.06 0 -0.05
        rotation -0.6610599311619936 0.661062359375166 0.35495960957472195 2.459422311325983
        children [
          USE WHEEL
        ]
        name "solid(2)"
        boundingObject USE WHEEL
        physics Physics {
        }
        linearVelocity -0.027396436768357096 1.8945449873489826e-08 -0.004759176775938592
        angularVelocity -0.7622461852914402 -0.3561883722426539 0.6472918518170471
      }
    }
    DEF WHEEL4 HingeJoint {
      jointParameters HingeJointParameters {
        position 3858.4645893342345
        anchor -0.06 0 -0.05
      }
      device [
        RotationalMotor {
          name "wheel4"
        }
      ]
      endPoint Solid {
        translation -0.06 0 -0.05
        rotation 0.2786748546020782 -0.2786758782338565 0.9190647856941857 1.6550986310996445
        children [
          USE WHEEL
        ]
        name "solid(3)"
        boundingObject USE WHEEL
        physics Physics {
        }
        linearVelocity 0.0002556403133230018 -6.069082853780983e-09 0.027802634756146843
        angularVelocity 0.7622458306491271 -0.3561881952251531 -0.6472920966551217
      }
    }
    DEF DS_RIGHT DistanceSensor {
      translation -0.03 0 0.1
      rotation 0 1 0 -1.87079
      children [
        Shape {
          appearance PBRAppearance {
            baseColor 0.184314 0.596078 0.847059
            roughness 1
            metalness 0
          }
          geometry Box {
            size 0.01 0.01 0.01
          }
        }
      ]
      name "ds_right"
    }
    DEF DS_LEFT DistanceSensor {
      translation 0.03 0 0.1
      rotation 0 1 0 -1.27079
      children [
        Shape {
          appearance PBRAppearance {
            baseColor 0.184314 0.596078 0.847059
            roughness 1
            metalness 0
          }
          geometry Box {
            size 0.01 0.01 0.01
          }
        }
      ]
      name "ds_left"
    }
  ]
  boundingObject USE BODY
  physics Physics {
    density -1
    mass 1
  }
  controller "four_wheels_collision_avoidance"
  controllerArgs [
    ""
    ""
    ""
    ""
    ""
    ""
    ""
    ""
  ]
  linearVelocity -3.0139797105016364e-06 1.2181866265047417e-11 -9.267790278924924e-09
  angularVelocity -2.3740832500432505e-07 -0.35596470774846095 -7.630507520551161e-08
}
RectangleArena {
  floorSize 5 5
  floorTileSize 1 1
}
Obstacle {
  translation -1.65 0.025 1.28
}
Obstacle {
  translation 1.09 0.025 -1.05
  name "obstacle(1)"
}
Obstacle {
  translation -1.4 0.025 -1.48
  name "obstacle(2)"
}
Obstacle {
  translation 0 0.025 1.74
  name "obstacle(3)"
}
Obstacle {
  translation -0.5 0.025 -2.04
  name "obstacle(4)"
}
Obstacle {
  translation 0.78 0.025 1.1
  name "obstacle(5)"
}
Obstacle {
  translation -1.41 0.025 0
  name "obstacle(6)"
}
Obstacle {
  translation 0 0.025 -1.38
  name "obstacle(7)"
}
Obstacle {
  translation 1.29 0.025 0
  name "obstacle(8)"
}
